Workbook
Name RANK: '2026'!$F$7:$AM$11

Sheet RANK
A1: Runner | B1: cumulative runs
A2: =IFERROR(__xludf.DUMMYFUNCTION("query(transpose(RANK),""Select Col5, Col2 order by Col2 desc"",0)"),"Scott") -> Scott | B2: =IFERROR(__xludf.DUMMYFUNCTION("""COMPUTED_VALUE"""),150.0) -> 150
A3: =IFERROR(__xludf.DUMMYFUNCTION("""COMPUTED_VALUE"""),"Aaron") -> Aaron | B3: =IFERROR(__xludf.DUMMYFUNCTION("""COMPUTED_VALUE"""),137.0) -> 137
A4: =IFERROR(__xludf.DUMMYFUNCTION("""COMPUTED_VALUE"""),"Cam") -> Cam | B4: =IFERROR(__xludf.DUMMYFUNCTION("""COMPUTED_VALUE"""),129.0) -> 129
A5: =IFERROR(__xludf.DUMMYFUNCTION("""COMPUTED_VALUE"""),"Alex 👑") -> Alex 👑 | B5: =IFERROR(__xludf.DUMMYFUNCTION("""COMPUTED_VALUE"""),122.0) -> 122
A6: =IFERROR(__xludf.DUMMYFUNCTION("""COMPUTED_VALUE"""),"Col") -> Col | B6: =IFERROR(__xludf.DUMMYFUNCTION("""COMPUTED_VALUE"""),115.0) -> 115
A7: =IFERROR(__xludf.DUMMYFUNCTION("""COMPUTED_VALUE"""),"Adam") -> Adam | B7: =IFERROR(__xludf.DUMMYFUNCTION("""COMPUTED_VALUE"""),114.0) -> 114
A8: =IFERROR(__xludf.DUMMYFUNCTION("""COMPUTED_VALUE"""),"Grant") -> Grant | B8: =IFERROR(__xludf.DUMMYFUNCTION("""COMPUTED_VALUE"""),94.0) -> 94
A9: =IFERROR(__xludf.DUMMYFUNCTION("""COMPUTED_VALUE"""),"Toby") -> Toby | B9: =IFERROR(__xludf.DUMMYFUNCTION("""COMPUTED_VALUE"""),73.0) -> 73
A10: =IFERROR(__xludf.DUMMYFUNCTION("""COMPUTED_VALUE"""),"Kate B") -> Kate B | B10: =IFERROR(__xludf.DUMMYFUNCTION("""COMPUTED_VALUE"""),67.0) -> 67
A11: =IFERROR(__xludf.DUMMYFUNCTION("""COMPUTED_VALUE"""),"Joe") -> Joe | B11: =IFERROR(__xludf.DUMMYFUNCTION("""COMPUTED_VALUE"""),62.0) -> 62
A12: =IFERROR(__xludf.DUMMYFUNCTION("""COMPUTED_VALUE"""),"Shane") -> Shane | B12: =IFERROR(__xludf.DUMMYFUNCTION("""COMPUTED_VALUE"""),60.0) -> 60
A13: =IFERROR(__xludf.DUMMYFUNCTION("""COMPUTED_VALUE"""),"Darren") -> Darren | B13: =IFERROR(__xludf.DUMMYFUNCTION("""COMPUTED_VALUE"""),51.0) -> 51
A14: =IFERROR(__xludf.DUMMYFUNCTION("""COMPUTED_VALUE"""),"Ming") -> Ming | B14: =IFERROR(__xludf.DUMMYFUNCTION("""COMPUTED_VALUE"""),46.0) -> 46
A15: =IFERROR(__xludf.DUMMYFUNCTION("""COMPUTED_VALUE"""),"Claire") -> Claire | B15: =IFERROR(__xludf.DUMMYFUNCTION("""COMPUTED_VALUE"""),45.0) -> 45
A16: =IFERROR(__xludf.DUMMYFUNCTION("""COMPUTED_VALUE"""),"Anna") -> Anna | B16: =IFERROR(__xludf.DUMMYFUNCTION("""COMPUTED_VALUE"""),44.0) -> 44
A17: =IFERROR(__xludf.DUMMYFUNCTION("""COMPUTED_VALUE"""),"+1's") -> +1's | B17: =IFERROR(__xludf.DUMMYFUNCTION("""COMPUTED_VALUE"""),43.0) -> 43
A18: =IFERROR(__xludf.DUMMYFUNCTION("""COMPUTED_VALUE"""),"Wes") -> Wes | B18: =IFERROR(__xludf.DUMMYFUNCTION("""COMPUTED_VALUE"""),42.0) -> 42
A19: =IFERROR(__xludf.DUMMYFUNCTION("""COMPUTED_VALUE"""),"Celeste") -> Celeste | B19: =IFERROR(__xludf.DUMMYFUNCTION("""COMPUTED_VALUE"""),40.0) -> 40
A20: =IFERROR(__xludf.DUMMYFUNCTION("""COMPUTED_VALUE"""),"Rhys") -> Rhys | B20: =IFERROR(__xludf.DUMMYFUNCTION("""COMPUTED_VALUE"""),35.0) -> 35
A21: =IFERROR(__xludf.DUMMYFUNCTION("""COMPUTED_VALUE"""),"Alex B") -> Alex B | B21: =IFERROR(__xludf.DUMMYFUNCTION("""COMPUTED_VALUE"""),27.0) -> 27
A22: =IFERROR(__xludf.DUMMYFUNCTION("""COMPUTED_VALUE"""),"Liam") -> Liam | B22: =IFERROR(__xludf.DUMMYFUNCTION("""COMPUTED_VALUE"""),26.0) -> 26
A23: =IFERROR(__xludf.DUMMYFUNCTION("""COMPUTED_VALUE"""),"Dan") -> Dan | B23: =IFERROR(__xludf.DUMMYFUNCTION("""COMPUTED_VALUE"""),22.0) -> 22
A24: =IFERROR(__xludf.DUMMYFUNCTION("""COMPUTED_VALUE"""),"Chartt") -> Chartt | B24: =IFERROR(__xludf.DUMMYFUNCTION("""COMPUTED_VALUE"""),20.0) -> 20
A25: =IFERROR(__xludf.DUMMYFUNCTION("""COMPUTED_VALUE"""),"Laura E") -> Laura E | B25: =IFERROR(__xludf.DUMMYFUNCTION("""COMPUTED_VALUE"""),20.0) -> 20
A26: =IFERROR(__xludf.DUMMYFUNCTION("""COMPUTED_VALUE"""),"Fraser") -> Fraser | B26: =IFERROR(__xludf.DUMMYFUNCTION("""COMPUTED_VALUE"""),19.0) -> 19
A27: =IFERROR(__xludf.DUMMYFUNCTION("""COMPUTED_VALUE"""),"Dan B") -> Dan B | B27: =IFERROR(__xludf.DUMMYFUNCTION("""COMPUTED_VALUE"""),18.0) -> 18
A28: =IFERROR(__xludf.DUMMYFUNCTION("""COMPUTED_VALUE"""),"Alex Kr") -> Alex Kr | B28: =IFERROR(__xludf.DUMMYFUNCTION("""COMPUTED_VALUE"""),13.0) -> 13
A29: =IFERROR(__xludf.DUMMYFUNCTION("""COMPUTED_VALUE"""),"Jack") -> Jack | B29: =IFERROR(__xludf.DUMMYFUNCTION("""COMPUTED_VALUE"""),11.0) -> 11
A30: =IFERROR(__xludf.DUMMYFUNCTION("""COMPUTED_VALUE"""),"Rohan") -> Rohan | B30: =IFERROR(__xludf.DUMMYFUNCTION("""COMPUTED_VALUE"""),10.0) -> 10
A31: =IFERROR(__xludf.DUMMYFUNCTION("""COMPUTED_VALUE"""),"Deano") -> Deano | B31: =IFERROR(__xludf.DUMMYFUNCTION("""COMPUTED_VALUE"""),7.0) -> 7
A32: =IFERROR(__xludf.DUMMYFUNCTION("""COMPUTED_VALUE"""),"Tarquin") -> Tarquin | B32: =IFERROR(__xludf.DUMMYFUNCTION("""COMPUTED_VALUE"""),7.0) -> 7
A33: =IFERROR(__xludf.DUMMYFUNCTION("""COMPUTED_VALUE"""),"Laura K") -> Laura K | B33: =IFERROR(__xludf.DUMMYFUNCTION("""COMPUTED_VALUE"""),4.0) -> 4
A34: =IFERROR(__xludf.DUMMYFUNCTION("""COMPUTED_VALUE"""),"Sam") -> Sam | B34: =IFERROR(__xludf.DUMMYFUNCTION("""COMPUTED_VALUE"""),3.0) -> 3
A35: =IFERROR(__xludf.DUMMYFUNCTION("""COMPUTED_VALUE"""),"Tim") -> Tim | B35: =IFERROR(__xludf.DUMMYFUNCTION("""COMPUTED_VALUE"""),3.0) -> 3

Sheet 2026
A1: Notes:
A2: - MSBB run is 4-weekly from Oct to May (during beach season)
A3: - MSBB run is 2-weekly from Jun to Sep (while beach is eroded)
A4: - Neighbourhood Loop (fortnightly) runs from Jun to Sep (while beach is eroded)
E7: =sum(F7:AL7) -> 5291.13 | F7: =sumif(F12:F174,"=x",$E$12:$E$174) -> 504.62 | G7: =sumif(G12:G174,"=x",$E$12:$E$174) -> 322.51 | H7: =sumif(H12:H174,"=x",$E$12:$E$174) -> 423.91 | I7: =sumif(I12:I174,"=x",$E$12:$E$174) -> 218.04 | J7: =sumif(J12:J174,"=x",$E$12:$E$174) -> 8.68 | K7: =sumif(K12:K174,"=x",$E$12:$E$174) -> 135.8 | L7: =sumif(L12:L174,"=x",$E$12:$E$174) -> 312.35 | M7: =sumif(M12:M174,"=x",$E$12:$E$174) -> 133.11 | ... AM7: =sumif(AM12:AM174,"=x",$E$12:$E$174) -> 0
E8: cumulative | F8: =F9+F10 -> 137 | G8: =G9+G10 -> 114 | H8: =H9+H10 -> 122 | I8: =I9+I10 -> 27 | J8: =J9+J10 -> 13 | K8: =K9+K10 -> 44 | L8: =L9+L10 -> 129 | M8: =M9+M10 -> 40 | ... AM8: =AM9+AM10 -> 43
A9: Pub hol | B9: Special event | C9: Attendance not recorded | E9: 2025 | F9: ='2025'!F9 -> 88 | G9: ='2025'!G9 -> 80 | H9: ='2025'!H9 -> 82 | I9: ='2025'!I9 -> 5 | J9: ='2025'!J9 -> 12 | K9: ='2025'!K9 -> 29 | L9: ='2025'!L9 -> 99 | M9: ='2025'!M9 -> 25 | ... Q9: ='2025'!Q9 -> 15 | R9: 0 | S9: ='2025'!R9 -> 24 | T9: 0 | U9: ='2025'!S9 -> 19 | V9: ='2025'!T9 -> 55 | W9: ='2025'!U9 -> 9 | X9: ='2025'!V9 -> 51 | Y9: ='2025'!W9 -> 39 | Z9: ='2025'!X9 -> 20 | AA9: ='2025'!Y9 -> 4 | AB9: ='2025'!Z9 -> 17 | ... AM9: ='2025'!AK9 -> 26
E10: 2026 | F10: =countif(F12:F1067,"x") -> 49 | G10: =countif(G12:G1067,"x") -> 34 | H10: =countif(H12:H1067,"x") -> 40 | I10: =countif(I12:I1067,"x") -> 22 | J10: =countif(J12:J1067,"x") -> 1 | K10: =countif(K12:K1067,"x") -> 15 | L10: =countif(L12:L1067,"x") -> 30 | M10: =countif(M12:M1067,"x") -> 15 | ... AL10: =countif(AL12:AL1067,"x") -> 16 | AM10: =sum(AM12:AM1067) -> 17 | AN10: =sum(F10:AM10) -> 546 | AO10: =sum(AO12:AO172) -> 5458.51
A11: Date | B11: Meet | C11: Run | D11: Approx kms | E11: Actual kms | F11: Aaron | G11: Adam | H11: Alex 👑 | I11: Alex B | J11: Alex Kr | K11: Anna | L11: Cam | M11: Celeste | N11: Chartt | O11: Claire | P11: Col | Q11: Dan | R11: Dan B | S11: Darren | T11: Deano | U11: Fraser | V11: Grant | W11: Jack | X11: Joe | Y11: Kate B | Z11: Laura E | AA11: Laura K | AB11: Liam | AC11: Ming | AD11: Rhys | AE11: Rohan | AF11: Sam | AG11: Scott | AH11: Shane | AI11: Tarquin | AJ11: Tim | AK11: Toby | AL11: Wes | AM11: +1's
A12: 46024 | B12: Il Lido | C12: Soft Sand | D12: 7 | E12: 7.1 | G12: x | H12: x | K12: x | L12: x | AG12: x | AN12: =countif(F12:AL12,"x")+AM12 -> 5 | AO12: =AN12*E12 -> 35.5
A13: =A12+3 -> 46027 | B13: Drift | C13: **Cruise | D13: 10 | E13: 10.41 | F13: x | H13: x | R13: x | X13: x | Y13: x | AH13: x | AK13: x | AN13: =countif(F13:AL13,"x")+AM13 -> 7 | AO13: =AN13*E13 -> 72.87
A14: =A13+2 -> 46029 | B14: Filament | C14: Social | D14: 8 | E14: 8 | F14: x | G14: x | H14: x | K14: x | L14: x | M14: x | O14: x | Q14: x | X14: x | Y14: x | AD14: x | AE14: x | AG14: x | AH14: x | AI14: x | AK14: x | AM14: 2 | AN14: =countif(F14:AL14,"x")+AM14 -> 18 | AO14: =AN14*E14 -> 144
A15: =A14+2 -> 46031 | B15: Il Lido | C15: Soft Sand | D15: 7 | E15: 7.06 | F15: x | G15: x | H15: x | L15: x | AE15: x | AN15: =countif(F15:AL15,"x")+AM15 -> 5 | AO15: =AN15*E15 -> 35.3
A16: =A15+3 -> 46034 | B16: Drift | C16: Cruise | D16: 10 | E16: 10.42 | F16: x | H16: x | O16: x | R16: x | S16: x | V16: x | X16: x | Y16: x | AH16: x | AK16: x | AN16: =countif(F16:AL16,"x")+AM16 -> 10 | AO16: =AN16*E16 -> 104.2
A17: =A16+2 -> 46036 | B17: Filament | C17: Intervals | D17: 8 | E17: 8.68 | F17: x | G17: x | H17: x | J17: x | K17: x | L17: x | M17: x | Q17: x | S17: x | V17: x | X17: x | Y17: x | AG17: x | AK17: x | AN17: =countif(F17:AL17,"x")+AM17 -> 14 | AO17: =AN17*E17 -> 121.52
A18: =A17+2 -> 46038 | B18: MSBB | C18: River Loop | D18: 12.5 | E18: 12.3 | F18: x | G18: x | H18: x | L18: x | V18: x | AG18: x | AK18: x | AM18: 1 | AN18: =countif(F18:AL18,"x")+AM18 -> 8 | AO18: =AN18*E18 -> 98.4
A19: =A18+3 -> 46041 | B19: Drift | C19: Intervals | D19: 10 | E19: 10.85 | F19: x | H19: x | R19: x | S19: x | V19: x | X19: x | AB19: x | AH19: x | AK19: x | AN19: =countif(F19:AL19,"x")+AM19 -> 9 | AO19: =AN19*E19 -> 97.65
A20: =A19+2 -> 46043 | B20: Filament | C20: Lakes Loop | D20: 12.5 | E20: 12.31 | F20: x | G20: x | H20: x | L20: x | M20: x | O20: x | P20: x | S20: x | V20: x | X20: x | AD20: x | AG20: x | AH20: x | AK20: x | AL20: x | AN20: =countif(F20:AL20,"x")+AM20 -> 15 | AO20: =AN20*E20 -> 184.65
A21: =A20+2 -> 46045 | B21: Il Lido | C21: Soft Sand | D21: 7 | E21: 7.11 | F21: x | G21: x | L21: x | P21: x | AG21: x | AN21: =countif(F21:AL21,"x")+AM21 -> 5 | AO21: =AN21*E21 -> 35.55
A22: =A21+3 -> 46048 | B22: Filament | C22: Half - Invasion Day | D22: 21.1 | E22: 21.27 | F22: x | G22: x | L22: x | P22: x | AG22: x | AN22: =countif(F22:AL22,"x")+AM22 -> 5 | AO22: =AN22*E22 -> 106.35
A23: =A22 -> 46048 | B23: Filament | C23: 10k - Invasion Day | D23: 10 | E23: 10 | I23: x | AM23: 1 | AN23: =countif(F23:AL23,"x")+AM23 -> 2 | AO23: =AN23*E23 -> 20
A24: =A23+2 -> 46050 | B24: Filament | C24: Intervals | D24: 8 | E24: 8.77 | F24: x | G24: x | H24: x | I24: x | M24: x | N24: x | P24: x | V24: x | W24: x | X24: x | AG24: x | AK24: x | AL24: x | AN24: =countif(F24:AL24,"x")+AM24 -> 13 | AO24: =AN24*E24 -> 114.01
A25: =A24+2 -> 46052 | B25: Il Lido | C25: Soft Sand | D25: 7 | E25: 7.08 | F25: x | G25: x | P25: x | AC25: x | AG25: x | AN25: =countif(F25:AL25,"x")+AM25 -> 5 | AO25: =AN25*E25 -> 35.4
A26: =A25+3 -> 46055 | B26: Drift | C26: Intervals | D26: 10 | E26: 11 | I26: x | V26: x | X26: x | Y26: x | AC26: x | AK26: x | AN26: =countif(F26:AL26,"x")+AM26 -> 6 | AO26: =AN26*E26 -> 66
A27: =A26+2 -> 46057 | B27: Filament | C27: Social | D27: 8 | E27: 7.99 | F27: x | G27: x | H27: x | I27: x | K27: x | M27: x | N27: x | O27: x | P27: x | S27: x | T27: x | V27: x | X27: x | AC27: x | AD27: x | AG27: x | AK27: x | AM27: 1 | AN27: =countif(F27:AL27,"x")+AM27 -> 18 | AO27: =AN27*E27 -> 143.82
A28: =A27+2 -> 46059 | B28: Il Lido | C28: Soft Sand | D28: 7 | E28: 7.06 | F28: x | G28: x | P28: x | AC28: x | AG28: x | AN28: =countif(F28:AL28,"x")+AM28 -> 5 | AO28: =AN28*E28 -> 35.3
A29: =A28+3 -> 46062 | B29: Drift | C29: Cruise | D29: 10 | E29: 10.02 | H29: x | I29: x | R29: x | S29: x | V29: x | X29: x | Y29: x | AB29: x | AK29: x | AN29: =countif(F29:AL29,"x")+AM29 -> 9 | AO29: =AN29*E29 -> 90.18
A30: =A29+2 -> 46064 | B30: Filament | C30: Intervals | D30: 8 | E30: 8.26 | F30: x | G30: x | H30: x | K30: x | M30: x | N30: x | P30: x | S30: x | T30: x | V30: x | Y30: x | AB30: x | AG30: x | AH30: x | AI30: x | AK30: x | AM30: 1 | AN30: =countif(F30:AL30,"x")+AM30 -> 17 | AO30: =AN30*E30 -> 140.42
A31: =A30+2 -> 46066 | B31: MSBB | C31: River Loop | D31: 12.5 | E31: 12.47 | F31: x | G31: x | H31: x | I31: x | P31: x | V31: x | Y31: x | AG31: x | AH31: x | AN31: =countif(F31:AL31,"x")+AM31 -> 9 | AO31: =AN31*E31 -> 112.23
A32: =A31+3 -> 46069 | B32: Drift | C32: Intervals | D32: 10 | E32: 9 | I32: x | R32: x | V32: x | Y32: x | AB32: x | AN32: =countif(F32:AL32,"x")+AM32 -> 5 | AO32: =AN32*E32 -> 45
A33: =A32+2 -> 46071 | B33: Filament | C33: Lakes Loop | D33: 12.5 | E33: 12.34 | F33: x | G33: x | H33: x | I33: x | K33: x | P33: x | V33: x | Y33: x | AB33: x | AG33: x | AL33: x | AM33: 1 | AN33: =countif(F33:AL33,"x")+AM33 -> 12 | AO33: =AN33*E33 -> 148.08
A34: =A33+2 -> 46073 | B34: Il Lido | C34: Soft Sand | D34: 7 | E34: 7.05 | F34: x | G34: x | H34: x | AG34: x | AN34: =countif(F34:AL34,"x")+AM34 -> 4 | AO34: =AN34*E34 -> 28.2
A35: =A34+3 -> 46076 | B35: Drift | C35: Cruise | D35: 10 | E35: 10.45 | F35: x | H35: x | I35: x | R35: x | V35: x | Y35: x | AN35: =countif(F35:AL35,"x")+AM35 -> 6 | AO35: =AN35*E35 -> 62.7
A36: =A35+2 -> 46078 | B36: Filament | C36: Intervals | D36: 8 | E36: 8.03 | F36: x | G36: x | H36: x | I36: x | K36: x | L36: x | M36: x | P36: x | T36: x | V36: x | Y36: x | AD36: x | AG36: x | AK36: x | AL36: x | AM36: 1 | AN36: =countif(F36:AL36,"x")+AM36 -> 16 | AO36: =AN36*E36 -> 128.48
A37: =A36+2 -> 46080 | B37: Il Lido | C37: Soft Sand | D37: 7 | E37: 7.08 | G37: x | L37: x | AC37: x | AG37: x | AN37: =countif(F37:AL37,"x")+AM37 -> 4 | AO37: =AN37*E37 -> 28.32
A38: =A37+3 -> 46083 | B38: Drift | C38: Intervals | D38: 10 | E38: 10 | G38: x | H38: x | I38: x | R38: x | V38: x | X38: x | Y38: x | AG38: x | AK38: x | AN38: =countif(F38:AL38,"x")+AM38 -> 9 | AO38: =AN38*E38 -> 90
A39: =A38+2 -> 46085 | B39: Filament | C39: Social | D39: 8 | E39: 8 | F39: x | G39: x | H39: x | I39: x | L39: x | M39: x | N39: x | P39: x | S39: x | T39: x | V39: x | Y39: x | AG39: x | AK39: x | AL39: x | AN39: =countif(F39:AL39,"x")+AM39 -> 15 | AO39: =AN39*E39 -> 120
A40: =A39+2 -> 46087 | B40: Il Lido | C40: Soft Sand | D40: 7 | E40: 7.07 | F40: x | L40: x | P40: x | AG40: x | AN40: =countif(F40:AL40,"x")+AM40 -> 4 | AO40: =AN40*E40 -> 28.28
A41: =A40+3 -> 46090 | B41: Drift | C41: Cruise | D41: 10 | E41: 10.5 | I41: x | R41: x | S41: x | V41: x | Y41: x | AB41: x | AN41: =countif(F41:AL41,"x")+AM41 -> 6 | AO41: =AN41*E41 -> 63
A42: =A41+2 -> 46092 | B42: Filament | C42: Intervals | D42: 8 | E42: 8.67 | F42: x | G42: x | H42: x | L42: x | P42: x | S42: x | V42: x | Y42: x | AG42: x | AI42: x | AK42: x | AL42: x | AN42: =countif(F42:AL42,"x")+AM42 -> 12 | AO42: =AN42*E42 -> 104.04
...

Sheet 2025
A1: Notes: | H1: THINGS TO ADD: | AK1: Top 5
A2: - MSBB run is 4-weekly from Oct to May (during beach season) | H2: FCTC Cup | AK2: =large($F$9:$AJ$9,1) -> 106 | AL2: =index($F$8:$AJ$10,3,match(AK2,$F$9:$AJ$9,0)) -> Scott
A3: - MSBB run is 2-weekly from Jun to Sep (while beach is eroded) | H3: Unofficial events: eg. Rohan 28th bday | AK3: =large($F$9:$AJ$9,2) -> 99 | AL3: =index($F$8:$AJ$10,3,match(AK3,$F$9:$AJ$9,0)) -> Cam
A4: - Neighbourhood Loop (fortnightly) runs from Jun to Sep (while beach is eroded) | H4: NAMES TO ADD???? | O4: Jack Crago, Kate, Carson? | AK4: =large($F$9:$AJ$9,3) -> 88 | AL4: =index($F$8:$AJ$10,3,match(AK4,$F$9:$AJ$9,0)) -> Aaron
H5: REPRINT SHEET NEXT QUARTERLY SHEET ASAP | AK5: =large($F$9:$AJ$9,4) -> 82 | AL5: =index($F$8:$AJ$10,3,match(AK5,$F$9:$AJ$9,0)) -> Alex 👑
A6: COUNTUNIQUE | AK6: =large($F$9:$AJ$9,5) -> 80 | AL6: =index($F$8:$AJ$10,3,match(AK6,$F$9:$AJ$9,0)) -> Adam
A8: Pub hol | B8: Special event | C8: Attendance not recorded | E8: =sum(E11:E121)-E19-E46-E115-E116 -> 1097.41 | F8: =sumif(F11:F121,"=x",$E$11:$E$121) -> 915.32 | G8: =sumif(G11:G121,"=x",$E$11:$E$121) -> 808.67 | H8: =sumif(H11:H121,"=x",$E$11:$E$121) -> 836.79 | I8: =sumif(I11:I121,"=x",$E$11:$E$121) -> 48.11 | J8: =sumif(J11:J121,"=x",$E$11:$E$121) -> 107.57 | K8: =sumif(K11:K121,"=x",$E$11:$E$121) -> 301.85 | L8: =sumif(L11:L121,"=x",$E$11:$E$121) -> 995.2 | M8: =sumif(M11:M121,"=x",$E$11:$E$121) -> 253.79 | ... AJ8: =sumif(AJ11:AJ121,"=x",$E$11:$E$121) -> 255.35
F9: =countif(F11:F1016,"x") -> 88 | G9: =countif(G11:G1016,"x") -> 80 | H9: =countif(H11:H1016,"x") -> 82 | I9: =countif(I11:I1016,"x") -> 5 | J9: =countif(J11:J1016,"x") -> 12 | K9: =countif(K11:K1016,"x") -> 29 | L9: =countif(L11:L1016,"x") -> 99 | M9: =countif(M11:M1016,"x") -> 25 | ... AJ9: =countif(AJ11:AJ1016,"x") -> 26 | AK9: =sum(AK11:AK1016) -> 26 | AL9: =sum(F9:AK9) -> 1133 | AM9: =sum(AM11:AM121) -> 11403.1
A10: Date | B10: Meet | C10: Run | D10: Approx kms | E10: Actual kms | F10: Aaron | G10: Adam | H10: Alex 👑 | I10: Alex B | J10: Alex Kr | K10: Anna | L10: Cam | M10: Celeste | N10: Chartt | O10: Claire | P10: Col | Q10: Dan | R10: Darren | S10: Fraser | T10: Grant | U10: Jack | V10: Joe | W10: Kate B | X10: Laura E | Y10: Laura K | Z10: Liam | AA10: Ming | AB10: Rhys | AC10: Rohan | AD10: Sam | AE10: Scott | AF10: Shane | AG10: Tarquin | AH10: Tim | AI10: Toby | AJ10: Wes | AK10: +1's
A11: 45660 | B11: Il Lido | C11: Soft Sand | D11: 7 | E11: 7.07 | F11: x | L11: x | O11: x | AA11: x | AC11: x | AE11: x | AK11: 2 | AL11: =countif(F11:AJ11,"x")+AK11 -> 8 | AM11: =AL11*E11 -> 56.56
A12: =A11+5 -> 45665 | B12: Filament | C12: Social | D12: 8 | E12: 7.95 | F12: x | G12: x | H12: x | L12: x | O12: x | Q12: x | V12: x | X12: x | AA12: x | AE12: x | AF12: x | AG12: x | AI12: x | AK12: 1 | AL12: =countif(F12:AJ12,"x")+AK12 -> 14 | AM12: =AL12*E12 -> 111.3
A13: =A12+2 -> 45667 | B13: Il Lido | C13: Soft Sand | D13: 7 | E13: 7.1 | G13: x | H13: x | L13: x | AE13: x | AL13: =countif(F13:AJ13,"x")+AK13 -> 4 | AM13: =AL13*E13 -> 28.4
A14: =A13+5 -> 45672 | B14: Filament | C14: Intervals | D14: 8 | E14: 8.44 | F14: x | G14: x | H14: x | L14: x | O14: - | Q14: x | S14: x | V14: x | AC14: - | AE14: x | AF14: x | AI14: x | AL14: =countif(F14:AJ14,"x")+AK14 -> 10 | AM14: =AL14*E14 -> 84.4
A15: =A14+2 -> 45674 | B15: MSBB | C15: River Loop | D15: 12.5 | E15: 12.3 | F15: x | G15: x | H15: x | L15: x | AE15: x | AF15: x | AL15: =countif(F15:AJ15,"x")+AK15 -> 6 | AM15: =AL15*E15 -> 73.8
A16: =A15+5 -> 45679 | B16: Filament | C16: Lakes Loop | D16: 12.5 | E16: 12.33 | F16: x | G16: x | H16: x | L16: x | T16: x | V16: x | X16: x | AA16: x | AB16: x | AC16: x | AE16: x | AF16: x | AI16: x | AK16: 1 | AL16: =countif(F16:AJ16,"x")+AK16 -> 14 | AM16: =AL16*E16 -> 172.62
A17: =A16+2 -> 45681 | B17: Il Lido | C17: Soft Sand | D17: 7 | E17: 7.09 | F17: x | G17: x | H17: x | L17: x | AC17: x | AE17: x | AK17: 1 | AL17: =countif(F17:AJ17,"x")+AK17 -> 7 | AM17: =AL17*E17 -> 49.63
A18: 45684 | B18: Filament | C18: Half- Invasion Day | D18: 21.1 | E18: 21.11 | F18: x | G18: x | H18: x | L18: x | P18: x | T18: x | AC18: x | AE18: x | AF18: x | AL18: =countif(F18:AJ18,"x")+AK18 -> 9 | AM18: =AL18*E18 -> 189.99
A19: 45684 | B19: Filament | C19: 10k- Invasion Day | D19: 10 | E19: 10.32 | Q19: x | X19: x | AB19: x | AG19: x | AL19: =countif(F19:AJ19,"x")+AK19 -> 4 | AM19: =AL19*E19 -> 41.28
A20: =A17+5 -> 45686 | B20: Filament | C20: Intervals | D20: 8 | E20: 8.97 | F20: x | G20: x | H20: x | L20: x | O20: x | P20: x | T20: x | V20: x | X20: x | AB20: x | AC20: x | AE20: x | AF20: - | AG20: x | AI20: x | AL20: =countif(F20:AJ20,"x")+AK20 -> 14 | AM20: =AL20*E20 -> 125.58
A21: =A20+2 -> 45688 | B21: Il Lido | C21: Soft Sand | D21: 7 | E21: 7.08 | F21: x | G21: x | H21: x | L21: x | O21: x | P21: - | AC21: x | AE21: x | AF21: - | AL21: =countif(F21:AJ21,"x")+AK21 -> 7 | AM21: =AL21*E21 -> 49.56
A22: =A21+5 -> 45693 | B22: Filament | C22: Social | D22: 8 | E22: 8.01 | F22: x | G22: x | H22: x | L22: x | O22: - | P22: x | Q22: x | S22: x | T22: x | V22: x | X22: x | AB22: x | AC22: x | AE22: x | AF22: x | AI22: x | AL22: =countif(F22:AJ22,"x")+AK22 -> 15 | AM22: =AL22*E22 -> 120.15
A23: =A22+2 -> 45695 | B23: Il Lido | C23: Soft Sand | D23: 7 | E23: 7.14 | F23: x | G23: x | H23: x | L23: x | O23: x | AC23: x | AE23: x | AF23: x | AL23: =countif(F23:AJ23,"x")+AK23 -> 8 | AM23: =AL23*E23 -> 57.12
A24: =A23+5 -> 45700 | B24: Filament | C24: Intervals | D24: 8 | E24: 8.45 | F24: x | G24: x | H24: x | L24: x | O24: x | P24: x | Q24: x | S24: x | T24: x | V24: x | X24: x | AE24: x | AF24: x | AI24: x | AL24: =countif(F24:AJ24,"x")+AK24 -> 14 | AM24: =AL24*E24 -> 118.3
A25: =A24+2 -> 45702 | B25: MSBB | C25: River Loop | D25: 12.5 | E25: 12.37 | F25: x | G25: x | H25: - | L25: x | O25: - | P25: x | T25: x | AB25: - | AE25: x | AF25: x | AI25: x | AL25: =countif(F25:AJ25,"x")+AK25 -> 8 | AM25: =AL25*E25 -> 98.96
A26: =A25+5 -> 45707 | B26: Filament | C26: Lakes Loop | D26: 12.5 | E26: 12.3 | F26: x | G26: 🛕 | H26: x | L26: x | O26: x | P26: x | S26: x | T26: x | V26: x | W26: x | X26: x | Y26: x | AA26: x | AB26: x | AC26: sad face | AE26: x | AF26: x | AI26: x | AL26: =countif(F26:AJ26,"x")+AK26 -> 16 | AM26: =AL26*E26 -> 196.8
A27: =A26+2 -> 45709 | B27: Il Lido | C27: Soft Sand | D27: 7 | E27: 7.06 | F27: - | H27: x | L27: x | P27: x | AA27: x | AE27: x | AL27: =countif(F27:AJ27,"x")+AK27 -> 5 | AM27: =AL27*E27 -> 35.3
A28: =A27+5 -> 45714 | B28: Filament | C28: Intervals | D28: 8 | E28: 8.6 | F28: x | G28: 🛕 | H28: x | L28: x | O28: x | P28: x | S28: x | V28: x | Y28: x | AB28: - | AC28: 🛕 | AE28: x | AF28: x | AH28: x | AI28: 🛕 | AL28: =countif(F28:AJ28,"x")+AK28 -> 11 | AM28: =AL28*E28 -> 94.6
A29: =A28+2 -> 45716 | B29: Il Lido | C29: Soft Sand | D29: 7 | E29: 7.07 | F29: x | L29: x | P29: x | AE29: x | AF29: x | AI29: x | AL29: =countif(F29:AJ29,"x")+AK29 -> 6 | AM29: =AL29*E29 -> 42.42
A30: =A29+5 -> 45721 | B30: Filament | C30: Social | D30: 8 | E30: 8.06 | F30: x | G30: x | H30: x | J30: x | L30: x | O30: x | P30: x | S30: x | T30: x | V30: x | W30: x | X30: x | AA30: x | AB30: x | AD30: x | AE30: x | AF30: x | AI30: x | AK30: 2 | AL30: =countif(F30:AJ30,"x")+AK30 -> 20 | AM30: =AL30*E30 -> 161.2
A31: =A30+2 -> 45723 | B31: Il Lido | C31: Soft Sand | D31: 7 | E31: 7.08 | F31: x | G31: x | H31: x | L31: x | O31: x | P31: x | T31: x | AA31: x | AE31: x | AF31: x | AL31: =countif(F31:AJ31,"x")+AK31 -> 10 | AM31: =AL31*E31 -> 70.8
A32: =A31+5 -> 45728 | B32: Filament | C32: Intervals | D32: 8 | E32: 8.59 | F32: x | G32: x | H32: x | J32: x | L32: x | O32: - | P32: x | Q32: x | S32: x | T32: x | U32: x | V32: x | X32: x | Y32: x | AA32: x | AB32: x | AD32: x | AE32: x | AF32: x | AH32: x | AI32: x | AL32: =countif(F32:AJ32,"x")+AK32 -> 20 | AM32: =AL32*E32 -> 171.8
A33: =A32+2 -> 45730 | B33: Il Lido | C33: Soft Sand | D33: 7 | E33: 9.26 | F33: x | G33: x | H33: x | L33: x | O33: x | P33: x | T33: x | AA33: x | AE33: x | AF33: x | AI33: x | AL33: =countif(F33:AJ33,"x")+AK33 -> 11 | AM33: =AL33*E33 -> 101.86
A34: =A33+5 -> 45735 | B34: Filament | C34: Lakes Loop | D34: 12.5 | E34: 12.37 | F34: x | G34: x | H34: 🛕 | L34: x | O34: x | P34: x | S34: x | T34: x | U34: x | V34: x | X34: x | Y34: x | AA34: x | AB34: 🛕 | AE34: x | AF34: x | AH34: x | AI34: 🛕 | AL34: =countif(F34:AJ34,"x")+AK34 -> 15 | AM34: =AL34*E34 -> 185.55
A35: =A34+2 -> 45737 | B35: MSBB | C35: River Loop | D35: 12.5 | E35: 12.38 | F35: x | G35: x | J35: x | L35: x | O35: - | P35: x | AE35: x | AI35: - | AL35: =countif(F35:AJ35,"x")+AK35 -> 6 | AM35: =AL35*E35 -> 74.28
A36: =A35+5 -> 45742 | B36: Filament | C36: Intervals | D36: 8 | E36: 8.26 | F36: - | G36: x | H36: x | J36: x | L36: x | O36: x | P36: x | S36: x | T36: x | V36: x | X36: - | AB36: x | AD36: x | AE36: x | AF36: - | AI36: x | AL36: =countif(F36:AJ36,"x")+AK36 -> 13 | AM36: =AL36*E36 -> 107.38
A37: =A36+2 -> 45744 | B37: Il Lido | C37: Soft Sand | D37: 7 | E37: 7 | G37: x | H37: x | L37: x | P37: x | AE37: x | AL37: =countif(F37:AJ37,"x")+AK37 -> 5 | AM37: =AL37*E37 -> 35
A38: =A37+5 -> 45749 | B38: Filament | C38: Social | D38: 8 | E38: 7.96 | F38: x | G38: x | H38: x | J38: x | L38: x | P38: x | Q38: x | S38: x | T38: x | U38: x | W38: x | X38: x | Z38: x | AB38: x | AE38: x | AF38: x | AI38: x | AK38: 2 | AL38: =countif(F38:AJ38,"x")+AK38 -> 19 | AM38: =AL38*E38 -> 151.24
A39: =A38+2 -> 45751 | B39: Il Lido | C39: Soft Sand | D39: 7 | E39: 7.07 | F39: x | G39: x | H39: x | L39: x | AE39: x | AL39: =countif(F39:AJ39,"x")+AK39 -> 5 | AM39: =AL39*E39 -> 35.35
A40: =A39+5 -> 45756 | B40: Filament | C40: Intervals | D40: 8 | E40: 8.95 | F40: x | G40: x | H40: x | J40: x | L40: x | P40: x | R40: x | S40: x | T40: x | U40: x | V40: x | X40: x | AA40: x | AB40: x | AD40: - | AE40: x | AI40: x | AJ40: x | AK40: 1 | AL40: =countif(F40:AJ40,"x")+AK40 -> 18 | AM40: =AL40*E40 -> 161.1
A41: =A40+2 -> 45758 | B41: MSBB | C41: River Loop | D41: 12.5 | E41: 12.32 | F41: x | G41: x | H41: x | L41: x | O41: x | P41: x | V41: x | Z41: x | AB41: x | AE41: x | AI41: - | AL41: =countif(F41:AJ41,"x")+AK41 -> 10 | AM41: =AL41*E41 -> 123.2
...

Sheet Peeps
A1: Name | B1: Been in last 2 months?
A2: Aaron | B2: x | C2: {=if(B2:B1000="x",A2:A1000,"")} -> Aaron
A3: Adam | B3: x | C3: Adam
A4: Alex | B4: x | C4: Alex
A5: Angus
A6: Caleb
A7: Cam | B7: x | C7: Cam
A8: Claire | B8: x | C8: Claire
A9: Col | B9: x | C9: Col
A10: Dan | B10: x | C10: Dan
A11: Dev
A12: Fraser | B12: x | C12: Fraser
A13: Gen
A14: Grant | B14: x | C14: Grant
A15: Harry | B15: x | C15: Harry
A16: Jack Crago
A17: Joe | B17: x | C17: Joe
A18: Laura | B18: x | C18: Laura
A19: Ming | B19: x | C19: Ming
A20: Ming | B20: x | C20: Ming
A21: Rance | B21: x | C21: Rance
A22: Rhys (RJ) | B22: x | C22: Rhys (RJ)
A23: Rohan | B23: x | C23: Rohan
A24: Sam C
A25: Scott | B25: x | C25: Scott
A26: Shane | B26: x | C26: Shane
A27: Tarquin | B27: x | C27: Tarquin
A28: Toby | B28: x | C28: Toby
A29: Tom
A30: Wes

Sheet Sheet3
A1: Aaron | B1: Adam | C1: Alex | D1: Alex K | E1: Cam | F1: Claire | G1: Col | H1: Dan | I1: Fraser | J1: Grant | K1: Jack | L1: Joe | M1: Kate | N1: Laura E | O1: Laura K | P1: Ming | Q1: Rhys | R1: Rohan | S1: Sam | T1: Scott | U1: Shane | V1: Tarquin | W1: Tim | X1: Toby
A2: 23 | B2: 22 | C2: 22 | D2: 5 | E2: 27 | F2: 13 | G2: 18 | H2: 7 | I2: 10 | J2: 14 | K2: 3 | L2: 12 | M2: 3 | N2: 11 | O2: 4 | P2: 10 | Q2: 9 | R2: 8 | S2: 3 | T2: 27 | U2: 18 | V2: 3 | W2: 3 | X2: 14
A4: {=transpose(A1:X2)} -> Aaron | B4: 23
A5: Adam | B5: 22
A6: Alex | B6: 22
A7: Alex K | B7: 5
A8: Cam | B8: 27
A9: Claire | B9: 13
A10: Col | B10: 18
A11: Dan | B11: 7
A12: Fraser | B12: 10
A13: Grant | B13: 14
A14: Jack | B14: 3
A15: Joe | B15: 12
A16: Kate | B16: 3
... A28: +1's | B28: 9
